Started: 2022-10-10
Internal Server Error: /admin/crm/contract/add/
Traceback (most recent call last):
  File "C:\Users\xdeva\Documents\OC_projets\P12_devant_xavier\venv\lib\site-packages\django\db\models\fields\__init__.py", line 2018, in get_prep_value
    return int(value)
TypeError: int() argument must be a string, a bytes-like object or a real number, not 'Client'

The above exception was the direct cause of the following exception:

Traceback (most recent call last):
  File "C:\Users\xdeva\Documents\OC_projets\P12_devant_xavier\EpicEvents\crm\models.py", line 61, in save
    self.client = Client.objects.get(id=self.client)
  File "C:\Users\xdeva\Documents\OC_projets\P12_devant_xavier\venv\lib\site-packages\django\db\models\manager.py", line 85, in manager_method
    return getattr(self.get_queryset(), name)(*args, **kwargs)
  File "C:\Users\xdeva\Documents\OC_projets\P12_devant_xavier\venv\lib\site-packages\django\db\models\query.py", line 636, in get
    clone = self._chain() if self.query.combinator else self.filter(*args, **kwargs)
  File "C:\Users\xdeva\Documents\OC_projets\P12_devant_xavier\venv\lib\site-packages\django\db\models\query.py", line 1420, in filter
    return self._filter_or_exclude(False, args, kwargs)
  File "C:\Users\xdeva\Documents\OC_projets\P12_devant_xavier\venv\lib\site-packages\django\db\models\query.py", line 1438, in _filter_or_exclude
    clone._filter_or_exclude_inplace(negate, args, kwargs)
  File "C:\Users\xdeva\Documents\OC_projets\P12_devant_xavier\venv\lib\site-packages\django\db\models\query.py", line 1445, in _filter_or_exclude_inplace
    self._query.add_q(Q(*args, **kwargs))
  File "C:\Users\xdeva\Documents\OC_projets\P12_devant_xavier\venv\lib\site-packages\django\db\models\sql\query.py", line 1532, in add_q
    clause, _ = self._add_q(q_object, self.used_aliases)
  File "C:\Users\xdeva\Documents\OC_projets\P12_devant_xavier\venv\lib\site-packages\django\db\models\sql\query.py", line 1562, in _add_q
    child_clause, needed_inner = self.build_filter(
  File "C:\Users\xdeva\Documents\OC_projets\P12_devant_xavier\venv\lib\site-packages\django\db\models\sql\query.py", line 1478, in build_filter
    condition = self.build_lookup(lookups, col, value)
  File "C:\Users\xdeva\Documents\OC_projets\P12_devant_xavier\venv\lib\site-packages\django\db\models\sql\query.py", line 1303, in build_lookup
    lookup = lookup_class(lhs, rhs)
  File "C:\Users\xdeva\Documents\OC_projets\P12_devant_xavier\venv\lib\site-packages\django\db\models\lookups.py", line 27, in __init__
    self.rhs = self.get_prep_lookup()
  File "C:\Users\xdeva\Documents\OC_projets\P12_devant_xavier\venv\lib\site-packages\django\db\models\lookups.py", line 341, in get_prep_lookup
    return super().get_prep_lookup()
  File "C:\Users\xdeva\Documents\OC_projets\P12_devant_xavier\venv\lib\site-packages\django\db\models\lookups.py", line 85, in get_prep_lookup
    return self.lhs.output_field.get_prep_value(self.rhs)
  File "C:\Users\xdeva\Documents\OC_projets\P12_devant_xavier\venv\lib\site-packages\django\db\models\fields\__init__.py", line 2020, in get_prep_value
    raise e.__class__(
TypeError: Field 'id' expected a number but got Third Brave (BlackPebble).

During handling of the above exception, another exception occurred:

Traceback (most recent call last):
  File "C:\Users\xdeva\Documents\OC_projets\P12_devant_xavier\venv\lib\site-packages\django\core\handlers\exception.py", line 55, in inner
    response = get_response(request)
  File "C:\Users\xdeva\Documents\OC_projets\P12_devant_xavier\venv\lib\site-packages\django\core\handlers\base.py", line 197, in _get_response
    response = wrapped_callback(request, *callback_args, **callback_kwargs)
  File "C:\Users\xdeva\Documents\OC_projets\P12_devant_xavier\venv\lib\site-packages\django\contrib\admin\options.py", line 686, in wrapper
    return self.admin_site.admin_view(view)(*args, **kwargs)
  File "C:\Users\xdeva\Documents\OC_projets\P12_devant_xavier\venv\lib\site-packages\django\utils\decorators.py", line 133, in _wrapped_view
    response = view_func(request, *args, **kwargs)
  File "C:\Users\xdeva\Documents\OC_projets\P12_devant_xavier\venv\lib\site-packages\django\views\decorators\cache.py", line 62, in _wrapped_view_func
    response = view_func(request, *args, **kwargs)
  File "C:\Users\xdeva\Documents\OC_projets\P12_devant_xavier\venv\lib\site-packages\django\contrib\admin\sites.py", line 242, in inner
    return view(request, *args, **kwargs)
  File "C:\Users\xdeva\Documents\OC_projets\P12_devant_xavier\venv\lib\site-packages\django\contrib\admin\options.py", line 1890, in add_view
    return self.changeform_view(request, None, form_url, extra_context)
  File "C:\Users\xdeva\Documents\OC_projets\P12_devant_xavier\venv\lib\site-packages\django\utils\decorators.py", line 46, in _wrapper
    return bound_method(*args, **kwargs)
  File "C:\Users\xdeva\Documents\OC_projets\P12_devant_xavier\venv\lib\site-packages\django\utils\decorators.py", line 133, in _wrapped_view
    response = view_func(request, *args, **kwargs)
  File "C:\Users\xdeva\Documents\OC_projets\P12_devant_xavier\venv\lib\site-packages\django\contrib\admin\options.py", line 1750, in changeform_view
    return self._changeform_view(request, object_id, form_url, extra_context)
  File "C:\Users\xdeva\Documents\OC_projets\P12_devant_xavier\venv\lib\site-packages\django\contrib\admin\options.py", line 1802, in _changeform_view
    self.save_model(request, new_object, form, not add)
  File "C:\Users\xdeva\Documents\OC_projets\P12_devant_xavier\venv\lib\site-packages\django\contrib\admin\options.py", line 1225, in save_model
    obj.save()
  File "C:\Users\xdeva\Documents\OC_projets\P12_devant_xavier\EpicEvents\crm\models.py", line 64, in save
    raise ValidationError(message)
rest_framework.exceptions.ValidationError: [ErrorDetail(string='Invalid client id', code='invalid')]
"POST /admin/crm/contract/add/ HTTP/1.1" 500 187484
Internal Server Error: /admin/crm/contract/add/
Traceback (most recent call last):
  File "C:\Users\xdeva\Documents\OC_projets\P12_devant_xavier\venv\lib\site-packages\django\db\backends\utils.py", line 89, in _execute
    return self.cursor.execute(sql, params)
psycopg2.errors.NotNullViolation: ERREUR:  une valeur NULL viole la contrainte NOT NULL de la colonne « sales_contact_id » dans la relation « crm_contract »
DETAIL:  La ligne en échec contient (9, f, 2, 2022-10-10 20:28:53+00, 2022-10-10 20:28:55.634546+00, null, 3, null).


The above exception was the direct cause of the following exception:

Traceback (most recent call last):
  File "C:\Users\xdeva\Documents\OC_projets\P12_devant_xavier\venv\lib\site-packages\django\core\handlers\exception.py", line 55, in inner
    response = get_response(request)
  File "C:\Users\xdeva\Documents\OC_projets\P12_devant_xavier\venv\lib\site-packages\django\core\handlers\base.py", line 197, in _get_response
    response = wrapped_callback(request, *callback_args, **callback_kwargs)
  File "C:\Users\xdeva\Documents\OC_projets\P12_devant_xavier\venv\lib\site-packages\django\contrib\admin\options.py", line 686, in wrapper
    return self.admin_site.admin_view(view)(*args, **kwargs)
  File "C:\Users\xdeva\Documents\OC_projets\P12_devant_xavier\venv\lib\site-packages\django\utils\decorators.py", line 133, in _wrapped_view
    response = view_func(request, *args, **kwargs)
  File "C:\Users\xdeva\Documents\OC_projets\P12_devant_xavier\venv\lib\site-packages\django\views\decorators\cache.py", line 62, in _wrapped_view_func
    response = view_func(request, *args, **kwargs)
  File "C:\Users\xdeva\Documents\OC_projets\P12_devant_xavier\venv\lib\site-packages\django\contrib\admin\sites.py", line 242, in inner
    return view(request, *args, **kwargs)
  File "C:\Users\xdeva\Documents\OC_projets\P12_devant_xavier\venv\lib\site-packages\django\contrib\admin\options.py", line 1890, in add_view
    return self.changeform_view(request, None, form_url, extra_context)
  File "C:\Users\xdeva\Documents\OC_projets\P12_devant_xavier\venv\lib\site-packages\django\utils\decorators.py", line 46, in _wrapper
    return bound_method(*args, **kwargs)
  File "C:\Users\xdeva\Documents\OC_projets\P12_devant_xavier\venv\lib\site-packages\django\utils\decorators.py", line 133, in _wrapped_view
    response = view_func(request, *args, **kwargs)
  File "C:\Users\xdeva\Documents\OC_projets\P12_devant_xavier\venv\lib\site-packages\django\contrib\admin\options.py", line 1750, in changeform_view
    return self._changeform_view(request, object_id, form_url, extra_context)
  File "C:\Users\xdeva\Documents\OC_projets\P12_devant_xavier\venv\lib\site-packages\django\contrib\admin\options.py", line 1802, in _changeform_view
    self.save_model(request, new_object, form, not add)
  File "C:\Users\xdeva\Documents\OC_projets\P12_devant_xavier\venv\lib\site-packages\django\contrib\admin\options.py", line 1225, in save_model
    obj.save()
  File "C:\Users\xdeva\Documents\OC_projets\P12_devant_xavier\EpicEvents\crm\models.py", line 60, in save
    return super().save(**kwargs)
  File "C:\Users\xdeva\Documents\OC_projets\P12_devant_xavier\venv\lib\site-packages\django\db\models\base.py", line 831, in save
    self.save_base(
  File "C:\Users\xdeva\Documents\OC_projets\P12_devant_xavier\venv\lib\site-packages\django\db\models\base.py", line 882, in save_base
    updated = self._save_table(
  File "C:\Users\xdeva\Documents\OC_projets\P12_devant_xavier\venv\lib\site-packages\django\db\models\base.py", line 1025, in _save_table
    results = self._do_insert(
  File "C:\Users\xdeva\Documents\OC_projets\P12_devant_xavier\venv\lib\site-packages\django\db\models\base.py", line 1066, in _do_insert
    return manager._insert(
  File "C:\Users\xdeva\Documents\OC_projets\P12_devant_xavier\venv\lib\site-packages\django\db\models\manager.py", line 85, in manager_method
    return getattr(self.get_queryset(), name)(*args, **kwargs)
  File "C:\Users\xdeva\Documents\OC_projets\P12_devant_xavier\venv\lib\site-packages\django\db\models\query.py", line 1790, in _insert
    return query.get_compiler(using=using).execute_sql(returning_fields)
  File "C:\Users\xdeva\Documents\OC_projets\P12_devant_xavier\venv\lib\site-packages\django\db\models\sql\compiler.py", line 1657, in execute_sql
    cursor.execute(sql, params)
  File "C:\Users\xdeva\Documents\OC_projets\P12_devant_xavier\venv\lib\site-packages\django\db\backends\utils.py", line 103, in execute
    return super().execute(sql, params)
  File "C:\Users\xdeva\Documents\OC_projets\P12_devant_xavier\venv\lib\site-packages\django\db\backends\utils.py", line 67, in execute
    return self._execute_with_wrappers(
  File "C:\Users\xdeva\Documents\OC_projets\P12_devant_xavier\venv\lib\site-packages\django\db\backends\utils.py", line 80, in _execute_with_wrappers
    return executor(sql, params, many, context)
  File "C:\Users\xdeva\Documents\OC_projets\P12_devant_xavier\venv\lib\site-packages\django\db\backends\utils.py", line 84, in _execute
    with self.db.wrap_database_errors:
  File "C:\Users\xdeva\Documents\OC_projets\P12_devant_xavier\venv\lib\site-packages\django\db\utils.py", line 91, in __exit__
    raise dj_exc_value.with_traceback(traceback) from exc_value
  File "C:\Users\xdeva\Documents\OC_projets\P12_devant_xavier\venv\lib\site-packages\django\db\backends\utils.py", line 89, in _execute
    return self.cursor.execute(sql, params)
django.db.utils.IntegrityError: ERREUR:  une valeur NULL viole la contrainte NOT NULL de la colonne « sales_contact_id » dans la relation « crm_contract »
DETAIL:  La ligne en échec contient (9, f, 2, 2022-10-10 20:28:53+00, 2022-10-10 20:28:55.634546+00, null, 3, null).

"POST /admin/crm/contract/add/ HTTP/1.1" 500 192484
Internal Server Error: /contracts/
Traceback (most recent call last):
  File "C:\Users\xdeva\Documents\OC_projets\P12_devant_xavier\venv\lib\site-packages\django\core\handlers\exception.py", line 55, in inner
    response = get_response(request)
  File "C:\Users\xdeva\Documents\OC_projets\P12_devant_xavier\venv\lib\site-packages\django\core\handlers\base.py", line 197, in _get_response
    response = wrapped_callback(request, *callback_args, **callback_kwargs)
  File "C:\Users\xdeva\Documents\OC_projets\P12_devant_xavier\venv\lib\site-packages\django\views\decorators\csrf.py", line 54, in wrapped_view
    return view_func(*args, **kwargs)
  File "C:\Users\xdeva\Documents\OC_projets\P12_devant_xavier\venv\lib\site-packages\rest_framework\viewsets.py", line 125, in view
    return self.dispatch(request, *args, **kwargs)
  File "C:\Users\xdeva\Documents\OC_projets\P12_devant_xavier\venv\lib\site-packages\rest_framework\views.py", line 509, in dispatch
    response = self.handle_exception(exc)
  File "C:\Users\xdeva\Documents\OC_projets\P12_devant_xavier\venv\lib\site-packages\rest_framework\views.py", line 469, in handle_exception
    self.raise_uncaught_exception(exc)
  File "C:\Users\xdeva\Documents\OC_projets\P12_devant_xavier\venv\lib\site-packages\rest_framework\views.py", line 480, in raise_uncaught_exception
    raise exc
  File "C:\Users\xdeva\Documents\OC_projets\P12_devant_xavier\venv\lib\site-packages\rest_framework\views.py", line 506, in dispatch
    response = handler(request, *args, **kwargs)
  File "C:\Users\xdeva\Documents\OC_projets\P12_devant_xavier\venv\lib\site-packages\rest_framework\mixins.py", line 19, in create
    self.perform_create(serializer)
  File "C:\Users\xdeva\Documents\OC_projets\P12_devant_xavier\epicevents\crm\views.py", line 77, in perform_create
    serializer.save()
  File "C:\Users\xdeva\Documents\OC_projets\P12_devant_xavier\venv\lib\site-packages\rest_framework\serializers.py", line 212, in save
    self.instance = self.create(validated_data)
  File "C:\Users\xdeva\Documents\OC_projets\P12_devant_xavier\venv\lib\site-packages\rest_framework\serializers.py", line 962, in create
    instance = ModelClass._default_manager.create(**validated_data)
  File "C:\Users\xdeva\Documents\OC_projets\P12_devant_xavier\venv\lib\site-packages\django\db\models\manager.py", line 85, in manager_method
    return getattr(self.get_queryset(), name)(*args, **kwargs)
  File "C:\Users\xdeva\Documents\OC_projets\P12_devant_xavier\venv\lib\site-packages\django\db\models\query.py", line 669, in create
    obj = self.model(**kwargs)
  File "C:\Users\xdeva\Documents\OC_projets\P12_devant_xavier\venv\lib\site-packages\django\db\models\base.py", line 561, in __init__
    _setattr(self, field.name, rel_obj)
  File "C:\Users\xdeva\Documents\OC_projets\P12_devant_xavier\venv\lib\site-packages\django\db\models\fields\related_descriptors.py", line 235, in __set__
    raise ValueError(
ValueError: Cannot assign "'1'": "Contract.client" must be a "Client" instance.
Internal Server Error: /contracts/
Traceback (most recent call last):
  File "C:\Users\xdeva\Documents\OC_projets\P12_devant_xavier\venv\lib\site-packages\django\core\handlers\exception.py", line 55, in inner
    response = get_response(request)
  File "C:\Users\xdeva\Documents\OC_projets\P12_devant_xavier\venv\lib\site-packages\django\core\handlers\base.py", line 197, in _get_response
    response = wrapped_callback(request, *callback_args, **callback_kwargs)
  File "C:\Users\xdeva\Documents\OC_projets\P12_devant_xavier\venv\lib\site-packages\django\views\decorators\csrf.py", line 54, in wrapped_view
    return view_func(*args, **kwargs)
  File "C:\Users\xdeva\Documents\OC_projets\P12_devant_xavier\venv\lib\site-packages\rest_framework\viewsets.py", line 125, in view
    return self.dispatch(request, *args, **kwargs)
  File "C:\Users\xdeva\Documents\OC_projets\P12_devant_xavier\venv\lib\site-packages\rest_framework\views.py", line 509, in dispatch
    response = self.handle_exception(exc)
  File "C:\Users\xdeva\Documents\OC_projets\P12_devant_xavier\venv\lib\site-packages\rest_framework\views.py", line 469, in handle_exception
    self.raise_uncaught_exception(exc)
  File "C:\Users\xdeva\Documents\OC_projets\P12_devant_xavier\venv\lib\site-packages\rest_framework\views.py", line 480, in raise_uncaught_exception
    raise exc
  File "C:\Users\xdeva\Documents\OC_projets\P12_devant_xavier\venv\lib\site-packages\rest_framework\views.py", line 506, in dispatch
    response = handler(request, *args, **kwargs)
  File "C:\Users\xdeva\Documents\OC_projets\P12_devant_xavier\venv\lib\site-packages\rest_framework\mixins.py", line 19, in create
    self.perform_create(serializer)
  File "C:\Users\xdeva\Documents\OC_projets\P12_devant_xavier\epicevents\crm\views.py", line 77, in perform_create
    serializer.save()
  File "C:\Users\xdeva\Documents\OC_projets\P12_devant_xavier\venv\lib\site-packages\rest_framework\serializers.py", line 212, in save
    self.instance = self.create(validated_data)
  File "C:\Users\xdeva\Documents\OC_projets\P12_devant_xavier\venv\lib\site-packages\rest_framework\serializers.py", line 962, in create
    instance = ModelClass._default_manager.create(**validated_data)
  File "C:\Users\xdeva\Documents\OC_projets\P12_devant_xavier\venv\lib\site-packages\django\db\models\manager.py", line 85, in manager_method
    return getattr(self.get_queryset(), name)(*args, **kwargs)
  File "C:\Users\xdeva\Documents\OC_projets\P12_devant_xavier\venv\lib\site-packages\django\db\models\query.py", line 669, in create
    obj = self.model(**kwargs)
  File "C:\Users\xdeva\Documents\OC_projets\P12_devant_xavier\venv\lib\site-packages\django\db\models\base.py", line 561, in __init__
    _setattr(self, field.name, rel_obj)
  File "C:\Users\xdeva\Documents\OC_projets\P12_devant_xavier\venv\lib\site-packages\django\db\models\fields\related_descriptors.py", line 235, in __set__
    raise ValueError(
ValueError: Cannot assign "'2'": "Contract.client" must be a "Client" instance.
Internal Server Error: /contracts/
Traceback (most recent call last):
  File "C:\Users\xdeva\Documents\OC_projets\P12_devant_xavier\venv\lib\site-packages\django\core\handlers\exception.py", line 55, in inner
    response = get_response(request)
  File "C:\Users\xdeva\Documents\OC_projets\P12_devant_xavier\venv\lib\site-packages\django\core\handlers\base.py", line 197, in _get_response
    response = wrapped_callback(request, *callback_args, **callback_kwargs)
  File "C:\Users\xdeva\Documents\OC_projets\P12_devant_xavier\venv\lib\site-packages\django\views\decorators\csrf.py", line 54, in wrapped_view
    return view_func(*args, **kwargs)
  File "C:\Users\xdeva\Documents\OC_projets\P12_devant_xavier\venv\lib\site-packages\rest_framework\viewsets.py", line 125, in view
    return self.dispatch(request, *args, **kwargs)
  File "C:\Users\xdeva\Documents\OC_projets\P12_devant_xavier\venv\lib\site-packages\rest_framework\views.py", line 509, in dispatch
    response = self.handle_exception(exc)
  File "C:\Users\xdeva\Documents\OC_projets\P12_devant_xavier\venv\lib\site-packages\rest_framework\views.py", line 469, in handle_exception
    self.raise_uncaught_exception(exc)
  File "C:\Users\xdeva\Documents\OC_projets\P12_devant_xavier\venv\lib\site-packages\rest_framework\views.py", line 480, in raise_uncaught_exception
    raise exc
  File "C:\Users\xdeva\Documents\OC_projets\P12_devant_xavier\venv\lib\site-packages\rest_framework\views.py", line 506, in dispatch
    response = handler(request, *args, **kwargs)
  File "C:\Users\xdeva\Documents\OC_projets\P12_devant_xavier\venv\lib\site-packages\rest_framework\mixins.py", line 19, in create
    self.perform_create(serializer)
  File "C:\Users\xdeva\Documents\OC_projets\P12_devant_xavier\epicevents\crm\views.py", line 77, in perform_create
    serializer.save()
  File "C:\Users\xdeva\Documents\OC_projets\P12_devant_xavier\venv\lib\site-packages\rest_framework\serializers.py", line 212, in save
    self.instance = self.create(validated_data)
  File "C:\Users\xdeva\Documents\OC_projets\P12_devant_xavier\venv\lib\site-packages\rest_framework\serializers.py", line 962, in create
    instance = ModelClass._default_manager.create(**validated_data)
  File "C:\Users\xdeva\Documents\OC_projets\P12_devant_xavier\venv\lib\site-packages\django\db\models\manager.py", line 85, in manager_method
    return getattr(self.get_queryset(), name)(*args, **kwargs)
  File "C:\Users\xdeva\Documents\OC_projets\P12_devant_xavier\venv\lib\site-packages\django\db\models\query.py", line 669, in create
    obj = self.model(**kwargs)
  File "C:\Users\xdeva\Documents\OC_projets\P12_devant_xavier\venv\lib\site-packages\django\db\models\base.py", line 561, in __init__
    _setattr(self, field.name, rel_obj)
  File "C:\Users\xdeva\Documents\OC_projets\P12_devant_xavier\venv\lib\site-packages\django\db\models\fields\related_descriptors.py", line 235, in __set__
    raise ValueError(
ValueError: Cannot assign "'2'": "Contract.client" must be a "Client" instance.
Internal Server Error: /contracts/
Traceback (most recent call last):
  File "C:\Users\xdeva\Documents\OC_projets\P12_devant_xavier\venv\lib\site-packages\django\core\handlers\exception.py", line 55, in inner
    response = get_response(request)
  File "C:\Users\xdeva\Documents\OC_projets\P12_devant_xavier\venv\lib\site-packages\django\core\handlers\base.py", line 197, in _get_response
    response = wrapped_callback(request, *callback_args, **callback_kwargs)
  File "C:\Users\xdeva\Documents\OC_projets\P12_devant_xavier\venv\lib\site-packages\django\views\decorators\csrf.py", line 54, in wrapped_view
    return view_func(*args, **kwargs)
  File "C:\Users\xdeva\Documents\OC_projets\P12_devant_xavier\venv\lib\site-packages\rest_framework\viewsets.py", line 125, in view
    return self.dispatch(request, *args, **kwargs)
  File "C:\Users\xdeva\Documents\OC_projets\P12_devant_xavier\venv\lib\site-packages\rest_framework\views.py", line 509, in dispatch
    response = self.handle_exception(exc)
  File "C:\Users\xdeva\Documents\OC_projets\P12_devant_xavier\venv\lib\site-packages\rest_framework\views.py", line 469, in handle_exception
    self.raise_uncaught_exception(exc)
  File "C:\Users\xdeva\Documents\OC_projets\P12_devant_xavier\venv\lib\site-packages\rest_framework\views.py", line 480, in raise_uncaught_exception
    raise exc
  File "C:\Users\xdeva\Documents\OC_projets\P12_devant_xavier\venv\lib\site-packages\rest_framework\views.py", line 506, in dispatch
    response = handler(request, *args, **kwargs)
  File "C:\Users\xdeva\Documents\OC_projets\P12_devant_xavier\venv\lib\site-packages\rest_framework\mixins.py", line 19, in create
    self.perform_create(serializer)
  File "C:\Users\xdeva\Documents\OC_projets\P12_devant_xavier\epicevents\crm\views.py", line 77, in perform_create
    serializer.save()
  File "C:\Users\xdeva\Documents\OC_projets\P12_devant_xavier\venv\lib\site-packages\rest_framework\serializers.py", line 212, in save
    self.instance = self.create(validated_data)
  File "C:\Users\xdeva\Documents\OC_projets\P12_devant_xavier\venv\lib\site-packages\rest_framework\serializers.py", line 962, in create
    instance = ModelClass._default_manager.create(**validated_data)
  File "C:\Users\xdeva\Documents\OC_projets\P12_devant_xavier\venv\lib\site-packages\django\db\models\manager.py", line 85, in manager_method
    return getattr(self.get_queryset(), name)(*args, **kwargs)
  File "C:\Users\xdeva\Documents\OC_projets\P12_devant_xavier\venv\lib\site-packages\django\db\models\query.py", line 669, in create
    obj = self.model(**kwargs)
  File "C:\Users\xdeva\Documents\OC_projets\P12_devant_xavier\venv\lib\site-packages\django\db\models\base.py", line 561, in __init__
    _setattr(self, field.name, rel_obj)
  File "C:\Users\xdeva\Documents\OC_projets\P12_devant_xavier\venv\lib\site-packages\django\db\models\fields\related_descriptors.py", line 235, in __set__
    raise ValueError(
ValueError: Cannot assign "'1'": "Contract.client" must be a "Client" instance.
Internal Server Error: /contracts/
Traceback (most recent call last):
  File "C:\Users\xdeva\Documents\OC_projets\P12_devant_xavier\venv\lib\site-packages\django\core\handlers\exception.py", line 55, in inner
    response = get_response(request)
  File "C:\Users\xdeva\Documents\OC_projets\P12_devant_xavier\venv\lib\site-packages\django\core\handlers\base.py", line 197, in _get_response
    response = wrapped_callback(request, *callback_args, **callback_kwargs)
  File "C:\Users\xdeva\Documents\OC_projets\P12_devant_xavier\venv\lib\site-packages\django\views\decorators\csrf.py", line 54, in wrapped_view
    return view_func(*args, **kwargs)
  File "C:\Users\xdeva\Documents\OC_projets\P12_devant_xavier\venv\lib\site-packages\rest_framework\viewsets.py", line 125, in view
    return self.dispatch(request, *args, **kwargs)
  File "C:\Users\xdeva\Documents\OC_projets\P12_devant_xavier\venv\lib\site-packages\rest_framework\views.py", line 509, in dispatch
    response = self.handle_exception(exc)
  File "C:\Users\xdeva\Documents\OC_projets\P12_devant_xavier\venv\lib\site-packages\rest_framework\views.py", line 469, in handle_exception
    self.raise_uncaught_exception(exc)
  File "C:\Users\xdeva\Documents\OC_projets\P12_devant_xavier\venv\lib\site-packages\rest_framework\views.py", line 480, in raise_uncaught_exception
    raise exc
  File "C:\Users\xdeva\Documents\OC_projets\P12_devant_xavier\venv\lib\site-packages\rest_framework\views.py", line 506, in dispatch
    response = handler(request, *args, **kwargs)
  File "C:\Users\xdeva\Documents\OC_projets\P12_devant_xavier\venv\lib\site-packages\rest_framework\mixins.py", line 19, in create
    self.perform_create(serializer)
  File "C:\Users\xdeva\Documents\OC_projets\P12_devant_xavier\epicevents\crm\views.py", line 77, in perform_create
    serializer.save()
  File "C:\Users\xdeva\Documents\OC_projets\P12_devant_xavier\venv\lib\site-packages\rest_framework\serializers.py", line 212, in save
    self.instance = self.create(validated_data)
  File "C:\Users\xdeva\Documents\OC_projets\P12_devant_xavier\venv\lib\site-packages\rest_framework\serializers.py", line 962, in create
    instance = ModelClass._default_manager.create(**validated_data)
  File "C:\Users\xdeva\Documents\OC_projets\P12_devant_xavier\venv\lib\site-packages\django\db\models\manager.py", line 85, in manager_method
    return getattr(self.get_queryset(), name)(*args, **kwargs)
  File "C:\Users\xdeva\Documents\OC_projets\P12_devant_xavier\venv\lib\site-packages\django\db\models\query.py", line 669, in create
    obj = self.model(**kwargs)
  File "C:\Users\xdeva\Documents\OC_projets\P12_devant_xavier\venv\lib\site-packages\django\db\models\base.py", line 561, in __init__
    _setattr(self, field.name, rel_obj)
  File "C:\Users\xdeva\Documents\OC_projets\P12_devant_xavier\venv\lib\site-packages\django\db\models\fields\related_descriptors.py", line 235, in __set__
    raise ValueError(
ValueError: Cannot assign "'1'": "Contract.client" must be a "Client" instance.
Internal Server Error: /contracts/
Traceback (most recent call last):
  File "C:\Users\xdeva\Documents\OC_projets\P12_devant_xavier\venv\lib\site-packages\django\core\handlers\exception.py", line 55, in inner
    response = get_response(request)
  File "C:\Users\xdeva\Documents\OC_projets\P12_devant_xavier\venv\lib\site-packages\django\core\handlers\base.py", line 197, in _get_response
    response = wrapped_callback(request, *callback_args, **callback_kwargs)
  File "C:\Users\xdeva\Documents\OC_projets\P12_devant_xavier\venv\lib\site-packages\django\views\decorators\csrf.py", line 54, in wrapped_view
    return view_func(*args, **kwargs)
  File "C:\Users\xdeva\Documents\OC_projets\P12_devant_xavier\venv\lib\site-packages\rest_framework\viewsets.py", line 125, in view
    return self.dispatch(request, *args, **kwargs)
  File "C:\Users\xdeva\Documents\OC_projets\P12_devant_xavier\venv\lib\site-packages\rest_framework\views.py", line 509, in dispatch
    response = self.handle_exception(exc)
  File "C:\Users\xdeva\Documents\OC_projets\P12_devant_xavier\venv\lib\site-packages\rest_framework\views.py", line 469, in handle_exception
    self.raise_uncaught_exception(exc)
  File "C:\Users\xdeva\Documents\OC_projets\P12_devant_xavier\venv\lib\site-packages\rest_framework\views.py", line 480, in raise_uncaught_exception
    raise exc
  File "C:\Users\xdeva\Documents\OC_projets\P12_devant_xavier\venv\lib\site-packages\rest_framework\views.py", line 506, in dispatch
    response = handler(request, *args, **kwargs)
  File "C:\Users\xdeva\Documents\OC_projets\P12_devant_xavier\venv\lib\site-packages\rest_framework\mixins.py", line 19, in create
    self.perform_create(serializer)
  File "C:\Users\xdeva\Documents\OC_projets\P12_devant_xavier\epicevents\crm\views.py", line 77, in perform_create
    serializer.save()
  File "C:\Users\xdeva\Documents\OC_projets\P12_devant_xavier\venv\lib\site-packages\rest_framework\serializers.py", line 212, in save
    self.instance = self.create(validated_data)
  File "C:\Users\xdeva\Documents\OC_projets\P12_devant_xavier\venv\lib\site-packages\rest_framework\serializers.py", line 962, in create
    instance = ModelClass._default_manager.create(**validated_data)
  File "C:\Users\xdeva\Documents\OC_projets\P12_devant_xavier\venv\lib\site-packages\django\db\models\manager.py", line 85, in manager_method
    return getattr(self.get_queryset(), name)(*args, **kwargs)
  File "C:\Users\xdeva\Documents\OC_projets\P12_devant_xavier\venv\lib\site-packages\django\db\models\query.py", line 669, in create
    obj = self.model(**kwargs)
  File "C:\Users\xdeva\Documents\OC_projets\P12_devant_xavier\venv\lib\site-packages\django\db\models\base.py", line 561, in __init__
    _setattr(self, field.name, rel_obj)
  File "C:\Users\xdeva\Documents\OC_projets\P12_devant_xavier\venv\lib\site-packages\django\db\models\fields\related_descriptors.py", line 235, in __set__
    raise ValueError(
ValueError: Cannot assign "'2'": "Contract.client" must be a "Client" instance.
Internal Server Error: /contracts/
Traceback (most recent call last):
  File "C:\Users\xdeva\Documents\OC_projets\P12_devant_xavier\venv\lib\site-packages\django\core\handlers\exception.py", line 55, in inner
    response = get_response(request)
  File "C:\Users\xdeva\Documents\OC_projets\P12_devant_xavier\venv\lib\site-packages\django\core\handlers\base.py", line 197, in _get_response
    response = wrapped_callback(request, *callback_args, **callback_kwargs)
  File "C:\Users\xdeva\Documents\OC_projets\P12_devant_xavier\venv\lib\site-packages\django\views\decorators\csrf.py", line 54, in wrapped_view
    return view_func(*args, **kwargs)
  File "C:\Users\xdeva\Documents\OC_projets\P12_devant_xavier\venv\lib\site-packages\rest_framework\viewsets.py", line 125, in view
    return self.dispatch(request, *args, **kwargs)
  File "C:\Users\xdeva\Documents\OC_projets\P12_devant_xavier\venv\lib\site-packages\rest_framework\views.py", line 509, in dispatch
    response = self.handle_exception(exc)
  File "C:\Users\xdeva\Documents\OC_projets\P12_devant_xavier\venv\lib\site-packages\rest_framework\views.py", line 469, in handle_exception
    self.raise_uncaught_exception(exc)
  File "C:\Users\xdeva\Documents\OC_projets\P12_devant_xavier\venv\lib\site-packages\rest_framework\views.py", line 480, in raise_uncaught_exception
    raise exc
  File "C:\Users\xdeva\Documents\OC_projets\P12_devant_xavier\venv\lib\site-packages\rest_framework\views.py", line 506, in dispatch
    response = handler(request, *args, **kwargs)
  File "C:\Users\xdeva\Documents\OC_projets\P12_devant_xavier\venv\lib\site-packages\rest_framework\mixins.py", line 19, in create
    self.perform_create(serializer)
  File "C:\Users\xdeva\Documents\OC_projets\P12_devant_xavier\epicevents\crm\views.py", line 77, in perform_create
    serializer.save()
  File "C:\Users\xdeva\Documents\OC_projets\P12_devant_xavier\venv\lib\site-packages\rest_framework\serializers.py", line 212, in save
    self.instance = self.create(validated_data)
  File "C:\Users\xdeva\Documents\OC_projets\P12_devant_xavier\venv\lib\site-packages\rest_framework\serializers.py", line 962, in create
    instance = ModelClass._default_manager.create(**validated_data)
  File "C:\Users\xdeva\Documents\OC_projets\P12_devant_xavier\venv\lib\site-packages\django\db\models\manager.py", line 85, in manager_method
    return getattr(self.get_queryset(), name)(*args, **kwargs)
  File "C:\Users\xdeva\Documents\OC_projets\P12_devant_xavier\venv\lib\site-packages\django\db\models\query.py", line 669, in create
    obj = self.model(**kwargs)
  File "C:\Users\xdeva\Documents\OC_projets\P12_devant_xavier\venv\lib\site-packages\django\db\models\base.py", line 561, in __init__
    _setattr(self, field.name, rel_obj)
  File "C:\Users\xdeva\Documents\OC_projets\P12_devant_xavier\venv\lib\site-packages\django\db\models\fields\related_descriptors.py", line 235, in __set__
    raise ValueError(
ValueError: Cannot assign "'2'": "Contract.client" must be a "Client" instance.
Internal Server Error: /contracts/
Traceback (most recent call last):
  File "C:\Users\xdeva\Documents\OC_projets\P12_devant_xavier\venv\lib\site-packages\django\core\handlers\exception.py", line 55, in inner
    response = get_response(request)
  File "C:\Users\xdeva\Documents\OC_projets\P12_devant_xavier\venv\lib\site-packages\django\core\handlers\base.py", line 197, in _get_response
    response = wrapped_callback(request, *callback_args, **callback_kwargs)
  File "C:\Users\xdeva\Documents\OC_projets\P12_devant_xavier\venv\lib\site-packages\django\views\decorators\csrf.py", line 54, in wrapped_view
    return view_func(*args, **kwargs)
  File "C:\Users\xdeva\Documents\OC_projets\P12_devant_xavier\venv\lib\site-packages\rest_framework\viewsets.py", line 125, in view
    return self.dispatch(request, *args, **kwargs)
  File "C:\Users\xdeva\Documents\OC_projets\P12_devant_xavier\venv\lib\site-packages\rest_framework\views.py", line 509, in dispatch
    response = self.handle_exception(exc)
  File "C:\Users\xdeva\Documents\OC_projets\P12_devant_xavier\venv\lib\site-packages\rest_framework\views.py", line 469, in handle_exception
    self.raise_uncaught_exception(exc)
  File "C:\Users\xdeva\Documents\OC_projets\P12_devant_xavier\venv\lib\site-packages\rest_framework\views.py", line 480, in raise_uncaught_exception
    raise exc
  File "C:\Users\xdeva\Documents\OC_projets\P12_devant_xavier\venv\lib\site-packages\rest_framework\views.py", line 506, in dispatch
    response = handler(request, *args, **kwargs)
  File "C:\Users\xdeva\Documents\OC_projets\P12_devant_xavier\venv\lib\site-packages\rest_framework\mixins.py", line 19, in create
    self.perform_create(serializer)
  File "C:\Users\xdeva\Documents\OC_projets\P12_devant_xavier\epicevents\crm\views.py", line 77, in perform_create
    serializer.save()
  File "C:\Users\xdeva\Documents\OC_projets\P12_devant_xavier\venv\lib\site-packages\rest_framework\serializers.py", line 212, in save
    self.instance = self.create(validated_data)
  File "C:\Users\xdeva\Documents\OC_projets\P12_devant_xavier\venv\lib\site-packages\rest_framework\serializers.py", line 962, in create
    instance = ModelClass._default_manager.create(**validated_data)
  File "C:\Users\xdeva\Documents\OC_projets\P12_devant_xavier\venv\lib\site-packages\django\db\models\manager.py", line 85, in manager_method
    return getattr(self.get_queryset(), name)(*args, **kwargs)
  File "C:\Users\xdeva\Documents\OC_projets\P12_devant_xavier\venv\lib\site-packages\django\db\models\query.py", line 669, in create
    obj = self.model(**kwargs)
  File "C:\Users\xdeva\Documents\OC_projets\P12_devant_xavier\venv\lib\site-packages\django\db\models\base.py", line 561, in __init__
    _setattr(self, field.name, rel_obj)
  File "C:\Users\xdeva\Documents\OC_projets\P12_devant_xavier\venv\lib\site-packages\django\db\models\fields\related_descriptors.py", line 235, in __set__
    raise ValueError(
ValueError: Cannot assign "'1'": "Contract.client" must be a "Client" instance.
