Internal Server Error: /contracts/
Traceback (most recent call last):
  File "C:\Users\xdeva\Documents\OC_projets\P12_devant_xavier\venv\lib\site-packages\django\core\handlers\exception.py", line 55, in inner
    response = get_response(request)
  File "C:\Users\xdeva\Documents\OC_projets\P12_devant_xavier\venv\lib\site-packages\django\core\handlers\base.py", line 197, in _get_response
    response = wrapped_callback(request, *callback_args, **callback_kwargs)
  File "C:\Users\xdeva\Documents\OC_projets\P12_devant_xavier\venv\lib\site-packages\django\views\decorators\csrf.py", line 54, in wrapped_view
    return view_func(*args, **kwargs)
  File "C:\Users\xdeva\Documents\OC_projets\P12_devant_xavier\venv\lib\site-packages\rest_framework\viewsets.py", line 125, in view
    return self.dispatch(request, *args, **kwargs)
  File "C:\Users\xdeva\Documents\OC_projets\P12_devant_xavier\venv\lib\site-packages\rest_framework\views.py", line 509, in dispatch
    response = self.handle_exception(exc)
  File "C:\Users\xdeva\Documents\OC_projets\P12_devant_xavier\venv\lib\site-packages\rest_framework\views.py", line 469, in handle_exception
    self.raise_uncaught_exception(exc)
  File "C:\Users\xdeva\Documents\OC_projets\P12_devant_xavier\venv\lib\site-packages\rest_framework\views.py", line 480, in raise_uncaught_exception
    raise exc
  File "C:\Users\xdeva\Documents\OC_projets\P12_devant_xavier\venv\lib\site-packages\rest_framework\views.py", line 497, in dispatch
    self.initial(request, *args, **kwargs)
  File "C:\Users\xdeva\Documents\OC_projets\P12_devant_xavier\venv\lib\site-packages\rest_framework\views.py", line 415, in initial
    self.check_permissions(request)
  File "C:\Users\xdeva\Documents\OC_projets\P12_devant_xavier\venv\lib\site-packages\rest_framework\views.py", line 332, in check_permissions
    if not permission.has_permission(request, self):
  File "C:\Users\xdeva\Documents\OC_projets\P12_devant_xavier\venv\lib\site-packages\rest_framework\permissions.py", line 229, in has_permission
    queryset = self._queryset(view)
  File "C:\Users\xdeva\Documents\OC_projets\P12_devant_xavier\venv\lib\site-packages\rest_framework\permissions.py", line 212, in _queryset
    queryset = view.get_queryset()
  File "C:\Users\xdeva\Documents\OC_projets\P12_devant_xavier\EpicEvents\crm\views.py", line 103, in get_queryset
    raise FileNotFoundError
FileNotFoundError
"GET /contracts/ HTTP/1.1" 500 108588
Internal Server Error: /contracts/
Traceback (most recent call last):
  File "C:\Users\xdeva\Documents\OC_projets\P12_devant_xavier\venv\lib\site-packages\django\core\handlers\exception.py", line 55, in inner
    response = get_response(request)
  File "C:\Users\xdeva\Documents\OC_projets\P12_devant_xavier\venv\lib\site-packages\django\core\handlers\base.py", line 197, in _get_response
    response = wrapped_callback(request, *callback_args, **callback_kwargs)
  File "C:\Users\xdeva\Documents\OC_projets\P12_devant_xavier\venv\lib\site-packages\django\views\decorators\csrf.py", line 54, in wrapped_view
    return view_func(*args, **kwargs)
  File "C:\Users\xdeva\Documents\OC_projets\P12_devant_xavier\venv\lib\site-packages\rest_framework\viewsets.py", line 125, in view
    return self.dispatch(request, *args, **kwargs)
  File "C:\Users\xdeva\Documents\OC_projets\P12_devant_xavier\venv\lib\site-packages\rest_framework\views.py", line 509, in dispatch
    response = self.handle_exception(exc)
  File "C:\Users\xdeva\Documents\OC_projets\P12_devant_xavier\venv\lib\site-packages\rest_framework\views.py", line 469, in handle_exception
    self.raise_uncaught_exception(exc)
  File "C:\Users\xdeva\Documents\OC_projets\P12_devant_xavier\venv\lib\site-packages\rest_framework\views.py", line 480, in raise_uncaught_exception
    raise exc
  File "C:\Users\xdeva\Documents\OC_projets\P12_devant_xavier\venv\lib\site-packages\rest_framework\views.py", line 497, in dispatch
    self.initial(request, *args, **kwargs)
  File "C:\Users\xdeva\Documents\OC_projets\P12_devant_xavier\venv\lib\site-packages\rest_framework\views.py", line 415, in initial
    self.check_permissions(request)
  File "C:\Users\xdeva\Documents\OC_projets\P12_devant_xavier\venv\lib\site-packages\rest_framework\views.py", line 332, in check_permissions
    if not permission.has_permission(request, self):
  File "C:\Users\xdeva\Documents\OC_projets\P12_devant_xavier\venv\lib\site-packages\rest_framework\permissions.py", line 229, in has_permission
    queryset = self._queryset(view)
  File "C:\Users\xdeva\Documents\OC_projets\P12_devant_xavier\venv\lib\site-packages\rest_framework\permissions.py", line 212, in _queryset
    queryset = view.get_queryset()
  File "C:\Users\xdeva\Documents\OC_projets\P12_devant_xavier\EpicEvents\crm\views.py", line 103, in get_queryset
    raise FileNotFoundError
FileNotFoundError
"GET /contracts/ HTTP/1.1" 500 108588
Internal Server Error: /clients/
Traceback (most recent call last):
  File "C:\Users\xdeva\Documents\OC_projets\P12_devant_xavier\venv\lib\site-packages\django\core\handlers\exception.py", line 55, in inner
    response = get_response(request)
  File "C:\Users\xdeva\Documents\OC_projets\P12_devant_xavier\venv\lib\site-packages\django\core\handlers\base.py", line 197, in _get_response
    response = wrapped_callback(request, *callback_args, **callback_kwargs)
  File "C:\Users\xdeva\Documents\OC_projets\P12_devant_xavier\venv\lib\site-packages\django\views\decorators\csrf.py", line 54, in wrapped_view
    return view_func(*args, **kwargs)
  File "C:\Users\xdeva\Documents\OC_projets\P12_devant_xavier\venv\lib\site-packages\rest_framework\viewsets.py", line 125, in view
    return self.dispatch(request, *args, **kwargs)
  File "C:\Users\xdeva\Documents\OC_projets\P12_devant_xavier\venv\lib\site-packages\rest_framework\views.py", line 509, in dispatch
    response = self.handle_exception(exc)
  File "C:\Users\xdeva\Documents\OC_projets\P12_devant_xavier\venv\lib\site-packages\rest_framework\views.py", line 469, in handle_exception
    self.raise_uncaught_exception(exc)
  File "C:\Users\xdeva\Documents\OC_projets\P12_devant_xavier\venv\lib\site-packages\rest_framework\views.py", line 480, in raise_uncaught_exception
    raise exc
  File "C:\Users\xdeva\Documents\OC_projets\P12_devant_xavier\venv\lib\site-packages\rest_framework\views.py", line 497, in dispatch
    self.initial(request, *args, **kwargs)
  File "C:\Users\xdeva\Documents\OC_projets\P12_devant_xavier\venv\lib\site-packages\rest_framework\views.py", line 415, in initial
    self.check_permissions(request)
  File "C:\Users\xdeva\Documents\OC_projets\P12_devant_xavier\venv\lib\site-packages\rest_framework\views.py", line 332, in check_permissions
    if not permission.has_permission(request, self):
  File "C:\Users\xdeva\Documents\OC_projets\P12_devant_xavier\venv\lib\site-packages\rest_framework\permissions.py", line 230, in has_permission
    perms = self.get_required_permissions(request.method, queryset.model)
AttributeError: 'Response' object has no attribute 'model'
Internal Server Error: /clients/
Traceback (most recent call last):
  File "C:\Users\xdeva\Documents\OC_projets\P12_devant_xavier\venv\lib\site-packages\django\core\handlers\exception.py", line 55, in inner
    response = get_response(request)
  File "C:\Users\xdeva\Documents\OC_projets\P12_devant_xavier\venv\lib\site-packages\django\core\handlers\base.py", line 197, in _get_response
    response = wrapped_callback(request, *callback_args, **callback_kwargs)
  File "C:\Users\xdeva\Documents\OC_projets\P12_devant_xavier\venv\lib\site-packages\django\views\decorators\csrf.py", line 54, in wrapped_view
    return view_func(*args, **kwargs)
  File "C:\Users\xdeva\Documents\OC_projets\P12_devant_xavier\venv\lib\site-packages\rest_framework\viewsets.py", line 125, in view
    return self.dispatch(request, *args, **kwargs)
  File "C:\Users\xdeva\Documents\OC_projets\P12_devant_xavier\venv\lib\site-packages\rest_framework\views.py", line 509, in dispatch
    response = self.handle_exception(exc)
  File "C:\Users\xdeva\Documents\OC_projets\P12_devant_xavier\venv\lib\site-packages\rest_framework\views.py", line 469, in handle_exception
    self.raise_uncaught_exception(exc)
  File "C:\Users\xdeva\Documents\OC_projets\P12_devant_xavier\venv\lib\site-packages\rest_framework\views.py", line 480, in raise_uncaught_exception
    raise exc
  File "C:\Users\xdeva\Documents\OC_projets\P12_devant_xavier\venv\lib\site-packages\rest_framework\views.py", line 497, in dispatch
    self.initial(request, *args, **kwargs)
  File "C:\Users\xdeva\Documents\OC_projets\P12_devant_xavier\venv\lib\site-packages\rest_framework\views.py", line 415, in initial
    self.check_permissions(request)
  File "C:\Users\xdeva\Documents\OC_projets\P12_devant_xavier\venv\lib\site-packages\rest_framework\views.py", line 332, in check_permissions
    if not permission.has_permission(request, self):
  File "C:\Users\xdeva\Documents\OC_projets\P12_devant_xavier\venv\lib\site-packages\rest_framework\permissions.py", line 230, in has_permission
    perms = self.get_required_permissions(request.method, queryset.model)
AttributeError: 'Response' object has no attribute 'model'
Internal Server Error: /clients/
Traceback (most recent call last):
  File "C:\Users\xdeva\Documents\OC_projets\P12_devant_xavier\venv\lib\site-packages\django\core\handlers\exception.py", line 55, in inner
    response = get_response(request)
  File "C:\Users\xdeva\Documents\OC_projets\P12_devant_xavier\venv\lib\site-packages\django\core\handlers\base.py", line 197, in _get_response
    response = wrapped_callback(request, *callback_args, **callback_kwargs)
  File "C:\Users\xdeva\Documents\OC_projets\P12_devant_xavier\venv\lib\site-packages\django\views\decorators\csrf.py", line 54, in wrapped_view
    return view_func(*args, **kwargs)
  File "C:\Users\xdeva\Documents\OC_projets\P12_devant_xavier\venv\lib\site-packages\rest_framework\viewsets.py", line 125, in view
    return self.dispatch(request, *args, **kwargs)
  File "C:\Users\xdeva\Documents\OC_projets\P12_devant_xavier\venv\lib\site-packages\rest_framework\views.py", line 509, in dispatch
    response = self.handle_exception(exc)
  File "C:\Users\xdeva\Documents\OC_projets\P12_devant_xavier\venv\lib\site-packages\rest_framework\views.py", line 469, in handle_exception
    self.raise_uncaught_exception(exc)
  File "C:\Users\xdeva\Documents\OC_projets\P12_devant_xavier\venv\lib\site-packages\rest_framework\views.py", line 480, in raise_uncaught_exception
    raise exc
  File "C:\Users\xdeva\Documents\OC_projets\P12_devant_xavier\venv\lib\site-packages\rest_framework\views.py", line 497, in dispatch
    self.initial(request, *args, **kwargs)
  File "C:\Users\xdeva\Documents\OC_projets\P12_devant_xavier\venv\lib\site-packages\rest_framework\views.py", line 415, in initial
    self.check_permissions(request)
  File "C:\Users\xdeva\Documents\OC_projets\P12_devant_xavier\venv\lib\site-packages\rest_framework\views.py", line 332, in check_permissions
    if not permission.has_permission(request, self):
  File "C:\Users\xdeva\Documents\OC_projets\P12_devant_xavier\venv\lib\site-packages\rest_framework\permissions.py", line 230, in has_permission
    perms = self.get_required_permissions(request.method, queryset.model)
AttributeError: 'Response' object has no attribute 'model'
Internal Server Error: /clients/
Traceback (most recent call last):
  File "C:\Users\xdeva\Documents\OC_projets\P12_devant_xavier\venv\lib\site-packages\django\core\handlers\exception.py", line 55, in inner
    response = get_response(request)
  File "C:\Users\xdeva\Documents\OC_projets\P12_devant_xavier\venv\lib\site-packages\django\core\handlers\base.py", line 197, in _get_response
    response = wrapped_callback(request, *callback_args, **callback_kwargs)
  File "C:\Users\xdeva\Documents\OC_projets\P12_devant_xavier\venv\lib\site-packages\django\views\decorators\csrf.py", line 54, in wrapped_view
    return view_func(*args, **kwargs)
  File "C:\Users\xdeva\Documents\OC_projets\P12_devant_xavier\venv\lib\site-packages\rest_framework\viewsets.py", line 125, in view
    return self.dispatch(request, *args, **kwargs)
  File "C:\Users\xdeva\Documents\OC_projets\P12_devant_xavier\venv\lib\site-packages\rest_framework\views.py", line 509, in dispatch
    response = self.handle_exception(exc)
  File "C:\Users\xdeva\Documents\OC_projets\P12_devant_xavier\venv\lib\site-packages\rest_framework\views.py", line 469, in handle_exception
    self.raise_uncaught_exception(exc)
  File "C:\Users\xdeva\Documents\OC_projets\P12_devant_xavier\venv\lib\site-packages\rest_framework\views.py", line 480, in raise_uncaught_exception
    raise exc
  File "C:\Users\xdeva\Documents\OC_projets\P12_devant_xavier\venv\lib\site-packages\rest_framework\views.py", line 497, in dispatch
    self.initial(request, *args, **kwargs)
  File "C:\Users\xdeva\Documents\OC_projets\P12_devant_xavier\venv\lib\site-packages\rest_framework\views.py", line 415, in initial
    self.check_permissions(request)
  File "C:\Users\xdeva\Documents\OC_projets\P12_devant_xavier\venv\lib\site-packages\rest_framework\views.py", line 332, in check_permissions
    if not permission.has_permission(request, self):
  File "C:\Users\xdeva\Documents\OC_projets\P12_devant_xavier\venv\lib\site-packages\rest_framework\permissions.py", line 230, in has_permission
    perms = self.get_required_permissions(request.method, queryset.model)
AttributeError: 'Response' object has no attribute 'model'
Internal Server Error: /clients/
Traceback (most recent call last):
  File "C:\Users\xdeva\Documents\OC_projets\P12_devant_xavier\venv\lib\site-packages\django\core\handlers\exception.py", line 55, in inner
    response = get_response(request)
  File "C:\Users\xdeva\Documents\OC_projets\P12_devant_xavier\venv\lib\site-packages\django\core\handlers\base.py", line 197, in _get_response
    response = wrapped_callback(request, *callback_args, **callback_kwargs)
  File "C:\Users\xdeva\Documents\OC_projets\P12_devant_xavier\venv\lib\site-packages\django\views\decorators\csrf.py", line 54, in wrapped_view
    return view_func(*args, **kwargs)
  File "C:\Users\xdeva\Documents\OC_projets\P12_devant_xavier\venv\lib\site-packages\rest_framework\viewsets.py", line 125, in view
    return self.dispatch(request, *args, **kwargs)
  File "C:\Users\xdeva\Documents\OC_projets\P12_devant_xavier\venv\lib\site-packages\rest_framework\views.py", line 509, in dispatch
    response = self.handle_exception(exc)
  File "C:\Users\xdeva\Documents\OC_projets\P12_devant_xavier\venv\lib\site-packages\rest_framework\views.py", line 469, in handle_exception
    self.raise_uncaught_exception(exc)
  File "C:\Users\xdeva\Documents\OC_projets\P12_devant_xavier\venv\lib\site-packages\rest_framework\views.py", line 480, in raise_uncaught_exception
    raise exc
  File "C:\Users\xdeva\Documents\OC_projets\P12_devant_xavier\venv\lib\site-packages\rest_framework\views.py", line 497, in dispatch
    self.initial(request, *args, **kwargs)
  File "C:\Users\xdeva\Documents\OC_projets\P12_devant_xavier\venv\lib\site-packages\rest_framework\views.py", line 415, in initial
    self.check_permissions(request)
  File "C:\Users\xdeva\Documents\OC_projets\P12_devant_xavier\venv\lib\site-packages\rest_framework\views.py", line 332, in check_permissions
    if not permission.has_permission(request, self):
  File "C:\Users\xdeva\Documents\OC_projets\P12_devant_xavier\venv\lib\site-packages\rest_framework\permissions.py", line 230, in has_permission
    perms = self.get_required_permissions(request.method, queryset.model)
AttributeError: 'Response' object has no attribute 'model'
Internal Server Error: /clients/
Traceback (most recent call last):
  File "C:\Users\xdeva\Documents\OC_projets\P12_devant_xavier\venv\lib\site-packages\django\core\handlers\exception.py", line 55, in inner
    response = get_response(request)
  File "C:\Users\xdeva\Documents\OC_projets\P12_devant_xavier\venv\lib\site-packages\django\core\handlers\base.py", line 197, in _get_response
    response = wrapped_callback(request, *callback_args, **callback_kwargs)
  File "C:\Users\xdeva\Documents\OC_projets\P12_devant_xavier\venv\lib\site-packages\django\views\decorators\csrf.py", line 54, in wrapped_view
    return view_func(*args, **kwargs)
  File "C:\Users\xdeva\Documents\OC_projets\P12_devant_xavier\venv\lib\site-packages\rest_framework\viewsets.py", line 125, in view
    return self.dispatch(request, *args, **kwargs)
  File "C:\Users\xdeva\Documents\OC_projets\P12_devant_xavier\venv\lib\site-packages\rest_framework\views.py", line 509, in dispatch
    response = self.handle_exception(exc)
  File "C:\Users\xdeva\Documents\OC_projets\P12_devant_xavier\venv\lib\site-packages\rest_framework\views.py", line 469, in handle_exception
    self.raise_uncaught_exception(exc)
  File "C:\Users\xdeva\Documents\OC_projets\P12_devant_xavier\venv\lib\site-packages\rest_framework\views.py", line 480, in raise_uncaught_exception
    raise exc
  File "C:\Users\xdeva\Documents\OC_projets\P12_devant_xavier\venv\lib\site-packages\rest_framework\views.py", line 497, in dispatch
    self.initial(request, *args, **kwargs)
  File "C:\Users\xdeva\Documents\OC_projets\P12_devant_xavier\venv\lib\site-packages\rest_framework\views.py", line 415, in initial
    self.check_permissions(request)
  File "C:\Users\xdeva\Documents\OC_projets\P12_devant_xavier\venv\lib\site-packages\rest_framework\views.py", line 332, in check_permissions
    if not permission.has_permission(request, self):
  File "C:\Users\xdeva\Documents\OC_projets\P12_devant_xavier\venv\lib\site-packages\rest_framework\permissions.py", line 230, in has_permission
    perms = self.get_required_permissions(request.method, queryset.model)
AttributeError: 'Response' object has no attribute 'model'
Internal Server Error: /contracts/1/
Traceback (most recent call last):
  File "C:\Users\xdeva\Documents\OC_projets\P12_devant_xavier\venv\lib\site-packages\django\core\handlers\exception.py", line 55, in inner
    response = get_response(request)
  File "C:\Users\xdeva\Documents\OC_projets\P12_devant_xavier\venv\lib\site-packages\django\core\handlers\base.py", line 197, in _get_response
    response = wrapped_callback(request, *callback_args, **callback_kwargs)
  File "C:\Users\xdeva\Documents\OC_projets\P12_devant_xavier\venv\lib\site-packages\django\views\decorators\csrf.py", line 54, in wrapped_view
    return view_func(*args, **kwargs)
  File "C:\Users\xdeva\Documents\OC_projets\P12_devant_xavier\venv\lib\site-packages\rest_framework\viewsets.py", line 125, in view
    return self.dispatch(request, *args, **kwargs)
  File "C:\Users\xdeva\Documents\OC_projets\P12_devant_xavier\venv\lib\site-packages\rest_framework\views.py", line 509, in dispatch
    response = self.handle_exception(exc)
  File "C:\Users\xdeva\Documents\OC_projets\P12_devant_xavier\venv\lib\site-packages\rest_framework\views.py", line 469, in handle_exception
    self.raise_uncaught_exception(exc)
  File "C:\Users\xdeva\Documents\OC_projets\P12_devant_xavier\venv\lib\site-packages\rest_framework\views.py", line 480, in raise_uncaught_exception
    raise exc
  File "C:\Users\xdeva\Documents\OC_projets\P12_devant_xavier\venv\lib\site-packages\rest_framework\views.py", line 497, in dispatch
    self.initial(request, *args, **kwargs)
  File "C:\Users\xdeva\Documents\OC_projets\P12_devant_xavier\venv\lib\site-packages\rest_framework\views.py", line 415, in initial
    self.check_permissions(request)
  File "C:\Users\xdeva\Documents\OC_projets\P12_devant_xavier\venv\lib\site-packages\rest_framework\views.py", line 332, in check_permissions
    if not permission.has_permission(request, self):
  File "C:\Users\xdeva\Documents\OC_projets\P12_devant_xavier\venv\lib\site-packages\rest_framework\permissions.py", line 230, in has_permission
    perms = self.get_required_permissions(request.method, queryset.model)
AttributeError: 'Response' object has no attribute 'model'
Internal Server Error: /contracts/1/
Traceback (most recent call last):
  File "C:\Users\xdeva\Documents\OC_projets\P12_devant_xavier\venv\lib\site-packages\django\core\handlers\exception.py", line 55, in inner
    response = get_response(request)
  File "C:\Users\xdeva\Documents\OC_projets\P12_devant_xavier\venv\lib\site-packages\django\core\handlers\base.py", line 197, in _get_response
    response = wrapped_callback(request, *callback_args, **callback_kwargs)
  File "C:\Users\xdeva\Documents\OC_projets\P12_devant_xavier\venv\lib\site-packages\django\views\decorators\csrf.py", line 54, in wrapped_view
    return view_func(*args, **kwargs)
  File "C:\Users\xdeva\Documents\OC_projets\P12_devant_xavier\venv\lib\site-packages\rest_framework\viewsets.py", line 125, in view
    return self.dispatch(request, *args, **kwargs)
  File "C:\Users\xdeva\Documents\OC_projets\P12_devant_xavier\venv\lib\site-packages\rest_framework\views.py", line 509, in dispatch
    response = self.handle_exception(exc)
  File "C:\Users\xdeva\Documents\OC_projets\P12_devant_xavier\venv\lib\site-packages\rest_framework\views.py", line 469, in handle_exception
    self.raise_uncaught_exception(exc)
  File "C:\Users\xdeva\Documents\OC_projets\P12_devant_xavier\venv\lib\site-packages\rest_framework\views.py", line 480, in raise_uncaught_exception
    raise exc
  File "C:\Users\xdeva\Documents\OC_projets\P12_devant_xavier\venv\lib\site-packages\rest_framework\views.py", line 497, in dispatch
    self.initial(request, *args, **kwargs)
  File "C:\Users\xdeva\Documents\OC_projets\P12_devant_xavier\venv\lib\site-packages\rest_framework\views.py", line 415, in initial
    self.check_permissions(request)
  File "C:\Users\xdeva\Documents\OC_projets\P12_devant_xavier\venv\lib\site-packages\rest_framework\views.py", line 332, in check_permissions
    if not permission.has_permission(request, self):
  File "C:\Users\xdeva\Documents\OC_projets\P12_devant_xavier\venv\lib\site-packages\rest_framework\permissions.py", line 230, in has_permission
    perms = self.get_required_permissions(request.method, queryset.model)
AttributeError: 'Response' object has no attribute 'model'
Internal Server Error: /contracts/1/
Traceback (most recent call last):
  File "C:\Users\xdeva\Documents\OC_projets\P12_devant_xavier\venv\lib\site-packages\django\core\handlers\exception.py", line 55, in inner
    response = get_response(request)
  File "C:\Users\xdeva\Documents\OC_projets\P12_devant_xavier\venv\lib\site-packages\django\core\handlers\base.py", line 197, in _get_response
    response = wrapped_callback(request, *callback_args, **callback_kwargs)
  File "C:\Users\xdeva\Documents\OC_projets\P12_devant_xavier\venv\lib\site-packages\django\views\decorators\csrf.py", line 54, in wrapped_view
    return view_func(*args, **kwargs)
  File "C:\Users\xdeva\Documents\OC_projets\P12_devant_xavier\venv\lib\site-packages\rest_framework\viewsets.py", line 125, in view
    return self.dispatch(request, *args, **kwargs)
  File "C:\Users\xdeva\Documents\OC_projets\P12_devant_xavier\venv\lib\site-packages\rest_framework\views.py", line 509, in dispatch
    response = self.handle_exception(exc)
  File "C:\Users\xdeva\Documents\OC_projets\P12_devant_xavier\venv\lib\site-packages\rest_framework\views.py", line 469, in handle_exception
    self.raise_uncaught_exception(exc)
  File "C:\Users\xdeva\Documents\OC_projets\P12_devant_xavier\venv\lib\site-packages\rest_framework\views.py", line 480, in raise_uncaught_exception
    raise exc
  File "C:\Users\xdeva\Documents\OC_projets\P12_devant_xavier\venv\lib\site-packages\rest_framework\views.py", line 506, in dispatch
    response = handler(request, *args, **kwargs)
  File "C:\Users\xdeva\Documents\OC_projets\P12_devant_xavier\venv\lib\site-packages\rest_framework\mixins.py", line 68, in update
    self.perform_update(serializer)
  File "C:\Users\xdeva\Documents\OC_projets\P12_devant_xavier\epicevents\crm\views.py", line 86, in perform_update
    serializer.save(date_updated=datetime.now())
  File "C:\Users\xdeva\Documents\OC_projets\P12_devant_xavier\venv\lib\site-packages\rest_framework\serializers.py", line 207, in save
    self.instance = self.update(self.instance, validated_data)
  File "C:\Users\xdeva\Documents\OC_projets\P12_devant_xavier\venv\lib\site-packages\rest_framework\serializers.py", line 1004, in update
    setattr(instance, attr, value)
  File "C:\Users\xdeva\Documents\OC_projets\P12_devant_xavier\venv\lib\site-packages\django\db\models\fields\related_descriptors.py", line 235, in __set__
    raise ValueError(
ValueError: Cannot assign "'1'": "Contract.client" must be a "Client" instance.
